Workbook
Name _ftn1: 'Törnqvist Methodology'!#REF!
Name _ftn2: 'Törnqvist Methodology'!#REF!
Name _ftn3: 'Törnqvist Methodology'!#REF!
Name _ftnref1: 'Törnqvist Methodology'!#REF!
Name _ftnref2: 'Törnqvist Methodology'!#REF!
Name _ftnref3: 'Törnqvist Methodology'!#REF!
Name _Toc166695565: 'Törnqvist Methodology'!#REF!
Name _Toc166695566: 'Törnqvist Methodology'!#REF!
Name _Toc166695567: 'Törnqvist Methodology'!#REF!

Sheet README
A1: The Changing Wealth of Nations 2024
A2: Citation: | B2: TBD
A3: Report (pdf): | B3: TBD | C3: SEGUIR ARREGLANDO ACA, TRAERMELO A LAS NOTAS, Y AL ES Y OVERVIEW
A4: Data and methods: | B4: https://datacatalog.worldbank.org/dataset/wealth-accounting | C4: The Törnqvist volume index it is 'chained' together to make a time series by selecting a base year (2019) and then expressing other years in terms relative to the base year. For the base year, the chained Törnqvist volume index is normalized to 100. To make the index easier to understand, the chained volume index is converted into monetary terms, referred to as real asset values and expressed in “chained 2019 prices.”
A5: Release date: | B5: 45573
A6: File version: | B6: 45573
A7: IMPORTANT NOTE: | B7: The trends in total wealth and asset categories (produced, human, renewable, and nonrenewable natural capital) are based on the Törnqvist index, where the change in physical volumes of individual assets is weighted by their value shares. “Volume” here refers to the physical quantity of each asset, or a proxy for that quantity. For example, the volume of timber assets is measured in hectares, while the volume of oil assets is measured in barrels. Because these assets are measured in different units, the Törnqvist index allows us to combine them by weighting the change in each asset by its value share, making the changes unitless and allowing the aggregation of different asset types to obtain an overall measure of how the total volume has changed. The Törnqvist volume index it is 'chained' together to make a time series by selecting a base year (2019) and then expressing other years in terms relative to the base year. For the base year, the chained Törnqvist volume index is normalized to 100. To make the index easier to interpret, the chained volume index is converted into monetary terms using 2019 US dollars, referred to as real asset values and expressed in “chained 2019 dollars”. This adjustment captures the "real" value of assets while removing the effect of inflation and other price changes. For each individual asset (sub-components of the aggregate categories), the change between 1995 and 2020 follows the trend in physical volumes, but unlike the aggregate asset categories, the changes over time in individual assets are not weighted by their shares in total wealth.
A9: Instructions | B9: On the "Select a Country" tab, select a country from the dropdown list at the top of the sheet. This automatically populates the data and figures on that sheet.
A11: Definitions
A12: Unit | B12: Values are measured at market exchange rates in chained 2019 US dollars, using a country-specific GDP deflator
A13: Country | B13: World Bank economy
A14: Income | B14: World Bank income group in 2020
A15: Region | B15: World Bank region (all income levels)
A16: Region_developing | B16: World Bank region (low income, lower middle income, and upper middle income economies)
A17: Total wealth | B17: Sum of produced capital, renewable and nonrenewable natural capital, human capital, and net foreign assets
A18: Produced capital | B18: Value of machinery, buildings, equipment, and residential and nonresidential urban land
A19: Renewable natural capital | B19: Valuation of agricultural land (cropland and pastureland), forests (timber and forest ecosystem services), mangroves, fisheries and hydropower
A20: Nonrenewable natural capital | B20: Valuation of fossil fuel energy (oil, gas, and coal) and minerals (bauxite, copper, gold, iron ore, lead, nickel, phosphate, silver, tin, zinc, cobalt, molybdenum, and lithuim)
A21: Human capital | B21: Present value of future earnings for the working population over their lifetimes
A22: Net foreign assets | B22: Foreign assets minus foreign liabilities
A24: * Will update the below series code once the WDI series code for CWON 2024 data is finalized
A25: Wealth Accounts Series Code and Name
A26: Series Code | B26: Series Name
A27: NW.PCA.TO | B27: Produced capital (real chained 2019 US$)
A28: NW.PCA.PC | B28: Produced capital per capita (real chained 2019 US$)
A29: NW.NFA.TO | B29: Foreign assets (real chained 2019 US$)
A30: NW.NFA.PC | B30: Foreign assets per capita (real chained 2019 US$)
A31: NW.NFL.TO | B31: Foreign liabilities (real chained 2019 US$)
A32: NW.NFL.PC | B32: Foreign liabilities per capita (real chained 2019 US$)
A33: NW.NCA.TOTL.TO | B33: Renewable natural capital, total (real chained 2019 US$)
A34: NW.NCA.TOTL.PC | B34: Renewable natural capital per capita, total (real chained 2019 US$)
A35: NW.NCA.AGRI.TO | B35: Renewable natural capital, agricultural land (real chained 2019 US$)
A36: NW.NCA.AGRI.PC | B36: Renewable natural capital per capita, agricultural land (real chained 2019 US$)
A37: NW.NCA.FTIM.TO | B37: Renewable natural capital, timber (real chained 2019 US$)
... A98: NW.TOW.PC.CD | B98: National comprehensive wealth per capita (current US$)

Sheet Select a Country
B1: IMPORTANT NOTE: | C1: The trends in total wealth and asset categories (produced, human, renewable, and nonrenewable natural capital) are based on the Törnqvist index, where the change in physical volumes of individual assets is weighted by their value shares. “Volume” here refers to the physical quantity of each asset, or a proxy for that quantity. For example, the volume of timber assets is measured in hectares, while the volume of oil assets is measured in barrels. Because these assets are measured in different units, the Törnqvist index allows us to combine them by weighting the change in each asset by its value share, making the changes unitless and allowing the aggregation of different asset types to obtain an overall measure of how the total volume has changed. The Törnqvist volume index it is 'chained' together to make a time series by selecting a base year (2019) and then expressing other years in terms relative to the base year. For the base year, the chained Törnqvist volume index is normalized to 100. To make the index easier to interpret, the chained volume index is converted into monetary terms using 2019 US dollars, referred to as real asset values and expressed in “chained 2019 dollars”. This adjustment captures the "real" value of assets while removing the effect of inflation and other price changes. For each individual asset (sub-components of the aggregate categories), the change between 1995 and 2020 follows the trend in physical volumes, but unlike the aggregate asset categories, the changes over time in individual assets are not weighted by their shares in total wealth.
B3: Select a country below:
A4: Country | B4: Argentina | C4: =VLOOKUP($B$4,class!$A:$F,2,FALSE) -> ARG
A5: Income | B5: =VLOOKUP($B$4,class!$A:$F,3,FALSE) -> Upper middle income
A6: Region | B6: =VLOOKUP($B$4,class!$A:$F,5,FALSE) -> Latin America and Caribbean
B8: Millions, chained 2019 USD | C8: 1995 | D8: 1996 | E8: 1997 | F8: 1998 | G8: 1999 | H8: 2000 | I8: 2001 | J8: 2002 | K8: 2003 | L8: 2004 | M8: 2005 | N8: 2006 | O8: 2007 | P8: 2008 | Q8: 2009 | R8: 2010 | S8: 2011 | T8: 2012 | U8: 2013 | V8: 2014 | W8: 2015 | X8: 2016 | Y8: 2017 | Z8: 2018 | AA8: 2019 | AB8: 2020 | AC8: Percent change (1995 to 2020)
A9: 36 | B9: National comprehensive wealth index | C9: =IFERROR(VLOOKUP(CONCATENATE($C$4,".",C$8),country!$G:$CD,$A9,FALSE)/1000000,"..") -> 1775865.6 | D9: =IFERROR(VLOOKUP(CONCATENATE($C$4,".",D$8),country!$G:$CD,$A9,FALSE)/1000000,"..") -> 1755387.1 | E9: =IFERROR(VLOOKUP(CONCATENATE($C$4,".",E$8),country!$G:$CD,$A9,FALSE)/1000000,"..") -> 1718201.8 | F9: =IFERROR(VLOOKUP(CONCATENATE($C$4,".",F$8),country!$G:$CD,$A9,FALSE)/1000000,"..") -> 1728758.8 | G9: =IFERROR(VLOOKUP(CONCATENATE($C$4,".",G$8),country!$G:$CD,$A9,FALSE)/1000000,"..") -> 1653061 | H9: =IFERROR(VLOOKUP(CONCATENATE($C$4,".",H$8),country!$G:$CD,$A9,FALSE)/1000000,"..") -> 1654586.9 | I9: =IFERROR(VLOOKUP(CONCATENATE($C$4,".",I$8),country!$G:$CD,$A9,FALSE)/1000000,"..") -> 1537978.1 | J9: =IFERROR(VLOOKUP(CONCATENATE($C$4,".",J$8),country!$G:$CD,$A9,FALSE)/1000000,"..") -> 2003756.1 | ... AB9: =IFERROR(VLOOKUP(CONCATENATE($C$4,".",AB$8),country!$G:$CD,$A9,FALSE)/1000000,"..") -> 3766127.3 | AC9: =IFERROR(AB9/C9-1,"..") -> 1.1207276
A10: 3 | B10: Produced capital | C10: =IFERROR(VLOOKUP(CONCATENATE($C$4,".",C$8),country!$G:$CD,$A10,FALSE)/1000000,"..") -> 391198.06 | D10: =IFERROR(VLOOKUP(CONCATENATE($C$4,".",D$8),country!$G:$CD,$A10,FALSE)/1000000,"..") -> 405064.18 | E10: =IFERROR(VLOOKUP(CONCATENATE($C$4,".",E$8),country!$G:$CD,$A10,FALSE)/1000000,"..") -> 423211.87 | F10: =IFERROR(VLOOKUP(CONCATENATE($C$4,".",F$8),country!$G:$CD,$A10,FALSE)/1000000,"..") -> 442622.75 | G10: =IFERROR(VLOOKUP(CONCATENATE($C$4,".",G$8),country!$G:$CD,$A10,FALSE)/1000000,"..") -> 456678.56 | H10: =IFERROR(VLOOKUP(CONCATENATE($C$4,".",H$8),country!$G:$CD,$A10,FALSE)/1000000,"..") -> 468128.76 | I10: =IFERROR(VLOOKUP(CONCATENATE($C$4,".",I$8),country!$G:$CD,$A10,FALSE)/1000000,"..") -> 474772.76 | J10: =IFERROR(VLOOKUP(CONCATENATE($C$4,".",J$8),country!$G:$CD,$A10,FALSE)/1000000,"..") -> 471844.11 | ... AB10: =IFERROR(VLOOKUP(CONCATENATE($C$4,".",AB$8),country!$G:$CD,$A10,FALSE)/1000000,"..") -> 827744.06 | AC10: =IFERROR(AB10/C10-1,"..") -> 1.1159207
A11: 33 | B11: Human capital | C11: =IFERROR(VLOOKUP(CONCATENATE($C$4,".",C$8),country!$G:$CD,$A11,FALSE)/1000000,"..") -> 1455187.3 | D11: =IFERROR(VLOOKUP(CONCATENATE($C$4,".",D$8),country!$G:$CD,$A11,FALSE)/1000000,"..") -> 1526475.9 | E11: =IFERROR(VLOOKUP(CONCATENATE($C$4,".",E$8),country!$G:$CD,$A11,FALSE)/1000000,"..") -> 1617412.2 | F11: =IFERROR(VLOOKUP(CONCATENATE($C$4,".",F$8),country!$G:$CD,$A11,FALSE)/1000000,"..") -> 1697522.9 | G11: =IFERROR(VLOOKUP(CONCATENATE($C$4,".",G$8),country!$G:$CD,$A11,FALSE)/1000000,"..") -> 1684917.5 | H11: =IFERROR(VLOOKUP(CONCATENATE($C$4,".",H$8),country!$G:$CD,$A11,FALSE)/1000000,"..") -> 1688360.8 | I11: =IFERROR(VLOOKUP(CONCATENATE($C$4,".",I$8),country!$G:$CD,$A11,FALSE)/1000000,"..") -> 1664920.6 | J11: =IFERROR(VLOOKUP(CONCATENATE($C$4,".",J$8),country!$G:$CD,$A11,FALSE)/1000000,"..") -> 1616374.1 | ... AB11: =IFERROR(VLOOKUP(CONCATENATE($C$4,".",AB$8),country!$G:$CD,$A11,FALSE)/1000000,"..") -> 2567714.5 | AC11: =IFERROR(AB11/C11-1,"..") -> 0.76452507
A12: 6 | B12: Renewable natural capital | C12: =IFERROR(VLOOKUP(CONCATENATE($C$4,".",C$8),country!$G:$CD,$A12,FALSE)/1000000,"..") -> 327340.87 | D12: =IFERROR(VLOOKUP(CONCATENATE($C$4,".",D$8),country!$G:$CD,$A12,FALSE)/1000000,"..") -> 319336.11 | E12: =IFERROR(VLOOKUP(CONCATENATE($C$4,".",E$8),country!$G:$CD,$A12,FALSE)/1000000,"..") -> 326455.81 | F12: =IFERROR(VLOOKUP(CONCATENATE($C$4,".",F$8),country!$G:$CD,$A12,FALSE)/1000000,"..") -> 322636.67 | G12: =IFERROR(VLOOKUP(CONCATENATE($C$4,".",G$8),country!$G:$CD,$A12,FALSE)/1000000,"..") -> 313995.9 | H12: =IFERROR(VLOOKUP(CONCATENATE($C$4,".",H$8),country!$G:$CD,$A12,FALSE)/1000000,"..") -> 324956.51 | I12: =IFERROR(VLOOKUP(CONCATENATE($C$4,".",I$8),country!$G:$CD,$A12,FALSE)/1000000,"..") -> 341265.34 | J12: =IFERROR(VLOOKUP(CONCATENATE($C$4,".",J$8),country!$G:$CD,$A12,FALSE)/1000000,"..") -> 338535.43 | ... AB12: =IFERROR(VLOOKUP(CONCATENATE($C$4,".",AB$8),country!$G:$CD,$A12,FALSE)/1000000,"..") -> 286052 | AC12: =IFERROR(AB12/C12-1,"..") -> -0.12613419
A13: 8 | B13: Forests, timber | C13: =IFERROR(VLOOKUP(CONCATENATE($C$4,".",C$8),country!$G:$CD,$A13,FALSE)/1000000,"..") -> 19882.89 | D13: =IFERROR(VLOOKUP(CONCATENATE($C$4,".",D$8),country!$G:$CD,$A13,FALSE)/1000000,"..") -> 19777.014 | E13: =IFERROR(VLOOKUP(CONCATENATE($C$4,".",E$8),country!$G:$CD,$A13,FALSE)/1000000,"..") -> 19671.137 | F13: =IFERROR(VLOOKUP(CONCATENATE($C$4,".",F$8),country!$G:$CD,$A13,FALSE)/1000000,"..") -> 19565.26 | G13: =IFERROR(VLOOKUP(CONCATENATE($C$4,".",G$8),country!$G:$CD,$A13,FALSE)/1000000,"..") -> 19459.384 | H13: =IFERROR(VLOOKUP(CONCATENATE($C$4,".",H$8),country!$G:$CD,$A13,FALSE)/1000000,"..") -> 19353.507 | I13: =IFERROR(VLOOKUP(CONCATENATE($C$4,".",I$8),country!$G:$CD,$A13,FALSE)/1000000,"..") -> 19170.049 | J13: =IFERROR(VLOOKUP(CONCATENATE($C$4,".",J$8),country!$G:$CD,$A13,FALSE)/1000000,"..") -> 18986.592 | ... AB13: =IFERROR(VLOOKUP(CONCATENATE($C$4,".",AB$8),country!$G:$CD,$A13,FALSE)/1000000,"..") -> 16567.432 | AC13: =IFERROR(AB13/C13-1,"..") -> -0.16674929
A14: 10 | B14: Forests, recreation, hunting, and fishing services (es1) | C14: =IFERROR(VLOOKUP(CONCATENATE($C$4,".",C$8),country!$G:$CD,$A14,FALSE)/1000000,"..") -> 4969.5562 | D14: =IFERROR(VLOOKUP(CONCATENATE($C$4,".",D$8),country!$G:$CD,$A14,FALSE)/1000000,"..") -> 4943.0933 | E14: =IFERROR(VLOOKUP(CONCATENATE($C$4,".",E$8),country!$G:$CD,$A14,FALSE)/1000000,"..") -> 4916.6303 | F14: =IFERROR(VLOOKUP(CONCATENATE($C$4,".",F$8),country!$G:$CD,$A14,FALSE)/1000000,"..") -> 4890.1674 | G14: =IFERROR(VLOOKUP(CONCATENATE($C$4,".",G$8),country!$G:$CD,$A14,FALSE)/1000000,"..") -> 4863.7044 | H14: =IFERROR(VLOOKUP(CONCATENATE($C$4,".",H$8),country!$G:$CD,$A14,FALSE)/1000000,"..") -> 4837.2415 | I14: =IFERROR(VLOOKUP(CONCATENATE($C$4,".",I$8),country!$G:$CD,$A14,FALSE)/1000000,"..") -> 4791.3878 | J14: =IFERROR(VLOOKUP(CONCATENATE($C$4,".",J$8),country!$G:$CD,$A14,FALSE)/1000000,"..") -> 4745.5342 | ... AB14: =IFERROR(VLOOKUP(CONCATENATE($C$4,".",AB$8),country!$G:$CD,$A14,FALSE)/1000000,"..") -> 4140.8862 | AC14: =IFERROR(AB14/C14-1,"..") -> -0.16674929
A15: 11 | B15: Forests, non-wood forest products (es2) | C15: =IFERROR(VLOOKUP(CONCATENATE($C$4,".",C$8),country!$G:$CD,$A15,FALSE)/1000000,"..") -> 9190.9726 | D15: =IFERROR(VLOOKUP(CONCATENATE($C$4,".",D$8),country!$G:$CD,$A15,FALSE)/1000000,"..") -> 9142.0306 | E15: =IFERROR(VLOOKUP(CONCATENATE($C$4,".",E$8),country!$G:$CD,$A15,FALSE)/1000000,"..") -> 9093.0885 | F15: =IFERROR(VLOOKUP(CONCATENATE($C$4,".",F$8),country!$G:$CD,$A15,FALSE)/1000000,"..") -> 9044.1465 | G15: =IFERROR(VLOOKUP(CONCATENATE($C$4,".",G$8),country!$G:$CD,$A15,FALSE)/1000000,"..") -> 8995.2044 | H15: =IFERROR(VLOOKUP(CONCATENATE($C$4,".",H$8),country!$G:$CD,$A15,FALSE)/1000000,"..") -> 8946.2624 | I15: =IFERROR(VLOOKUP(CONCATENATE($C$4,".",I$8),country!$G:$CD,$A15,FALSE)/1000000,"..") -> 8861.4581 | J15: =IFERROR(VLOOKUP(CONCATENATE($C$4,".",J$8),country!$G:$CD,$A15,FALSE)/1000000,"..") -> 8776.6538 | ... AB15: =IFERROR(VLOOKUP(CONCATENATE($C$4,".",AB$8),country!$G:$CD,$A15,FALSE)/1000000,"..") -> 7658.3844 | AC15: =IFERROR(AB15/C15-1,"..") -> -0.16674929
A16: 12 | B16: Forests, water retention services (es3) | C16: =IFERROR(VLOOKUP(CONCATENATE($C$4,".",C$8),country!$G:$CD,$A16,FALSE)/1000000,"..") -> 78348.703 | D16: =IFERROR(VLOOKUP(CONCATENATE($C$4,".",D$8),country!$G:$CD,$A16,FALSE)/1000000,"..") -> 77931.495 | E16: =IFERROR(VLOOKUP(CONCATENATE($C$4,".",E$8),country!$G:$CD,$A16,FALSE)/1000000,"..") -> 77514.287 | F16: =IFERROR(VLOOKUP(CONCATENATE($C$4,".",F$8),country!$G:$CD,$A16,FALSE)/1000000,"..") -> 77097.079 | G16: =IFERROR(VLOOKUP(CONCATENATE($C$4,".",G$8),country!$G:$CD,$A16,FALSE)/1000000,"..") -> 76679.872 | H16: =IFERROR(VLOOKUP(CONCATENATE($C$4,".",H$8),country!$G:$CD,$A16,FALSE)/1000000,"..") -> 76262.664 | I16: =IFERROR(VLOOKUP(CONCATENATE($C$4,".",I$8),country!$G:$CD,$A16,FALSE)/1000000,"..") -> 75539.747 | J16: =IFERROR(VLOOKUP(CONCATENATE($C$4,".",J$8),country!$G:$CD,$A16,FALSE)/1000000,"..") -> 74816.831 | ... AB16: =IFERROR(VLOOKUP(CONCATENATE($C$4,".",AB$8),country!$G:$CD,$A16,FALSE)/1000000,"..") -> 65284.112 | AC16: =IFERROR(AB16/C16-1,"..") -> -0.16674929
A17: 9 | B17: Mangroves | C17: =IFERROR(VLOOKUP(CONCATENATE($C$4,".",C$8),country!$G:$CD,$A17,FALSE)/1000000,"..") -> 0 | D17: =IFERROR(VLOOKUP(CONCATENATE($C$4,".",D$8),country!$G:$CD,$A17,FALSE)/1000000,"..") -> 0 | E17: =IFERROR(VLOOKUP(CONCATENATE($C$4,".",E$8),country!$G:$CD,$A17,FALSE)/1000000,"..") -> 0 | F17: =IFERROR(VLOOKUP(CONCATENATE($C$4,".",F$8),country!$G:$CD,$A17,FALSE)/1000000,"..") -> 0 | G17: =IFERROR(VLOOKUP(CONCATENATE($C$4,".",G$8),country!$G:$CD,$A17,FALSE)/1000000,"..") -> 0 | H17: =IFERROR(VLOOKUP(CONCATENATE($C$4,".",H$8),country!$G:$CD,$A17,FALSE)/1000000,"..") -> 0 | I17: =IFERROR(VLOOKUP(CONCATENATE($C$4,".",I$8),country!$G:$CD,$A17,FALSE)/1000000,"..") -> 0 | J17: =IFERROR(VLOOKUP(CONCATENATE($C$4,".",J$8),country!$G:$CD,$A17,FALSE)/1000000,"..") -> 0 | ... AB17: =IFERROR(VLOOKUP(CONCATENATE($C$4,".",AB$8),country!$G:$CD,$A17,FALSE)/1000000,"..") -> 0 | AC17: =IFERROR(AB17/C17-1,"..") -> ..
A18: 13 | B18: Fisheries | C18: =IFERROR(VLOOKUP(CONCATENATE($C$4,".",C$8),country!$G:$CD,$A18,FALSE)/1000000,"..") -> 2615.2576 | D18: =IFERROR(VLOOKUP(CONCATENATE($C$4,".",D$8),country!$G:$CD,$A18,FALSE)/1000000,"..") -> 2539.0788 | E18: =IFERROR(VLOOKUP(CONCATENATE($C$4,".",E$8),country!$G:$CD,$A18,FALSE)/1000000,"..") -> 2451.3813 | F18: =IFERROR(VLOOKUP(CONCATENATE($C$4,".",F$8),country!$G:$CD,$A18,FALSE)/1000000,"..") -> 2372.1139 | G18: =IFERROR(VLOOKUP(CONCATENATE($C$4,".",G$8),country!$G:$CD,$A18,FALSE)/1000000,"..") -> 2302.0723 | H18: =IFERROR(VLOOKUP(CONCATENATE($C$4,".",H$8),country!$G:$CD,$A18,FALSE)/1000000,"..") -> 2245.7755 | I18: =IFERROR(VLOOKUP(CONCATENATE($C$4,".",I$8),country!$G:$CD,$A18,FALSE)/1000000,"..") -> 2221.4369 | J18: =IFERROR(VLOOKUP(CONCATENATE($C$4,".",J$8),country!$G:$CD,$A18,FALSE)/1000000,"..") -> 2214.2776 | ... AB18: =IFERROR(VLOOKUP(CONCATENATE($C$4,".",AB$8),country!$G:$CD,$A18,FALSE)/1000000,"..") -> 2450.3742 | AC18: =IFERROR(AB18/C18-1,"..") -> -0.06304673
A19: 7 | B19: Agricultural land | C19: =IFERROR(VLOOKUP(CONCATENATE($C$4,".",C$8),country!$G:$CD,$A19,FALSE)/1000000,"..") -> 208047.46 | D19: =IFERROR(VLOOKUP(CONCATENATE($C$4,".",D$8),country!$G:$CD,$A19,FALSE)/1000000,"..") -> 208205.06 | E19: =IFERROR(VLOOKUP(CONCATENATE($C$4,".",E$8),country!$G:$CD,$A19,FALSE)/1000000,"..") -> 208356.17 | F19: =IFERROR(VLOOKUP(CONCATENATE($C$4,".",F$8),country!$G:$CD,$A19,FALSE)/1000000,"..") -> 208510.53 | G19: =IFERROR(VLOOKUP(CONCATENATE($C$4,".",G$8),country!$G:$CD,$A19,FALSE)/1000000,"..") -> 208643.76 | H19: =IFERROR(VLOOKUP(CONCATENATE($C$4,".",H$8),country!$G:$CD,$A19,FALSE)/1000000,"..") -> 208802.99 | I19: =IFERROR(VLOOKUP(CONCATENATE($C$4,".",I$8),country!$G:$CD,$A19,FALSE)/1000000,"..") -> 208958.97 | J19: =IFERROR(VLOOKUP(CONCATENATE($C$4,".",J$8),country!$G:$CD,$A19,FALSE)/1000000,"..") -> 209127.95 | ... AB19: =IFERROR(VLOOKUP(CONCATENATE($C$4,".",AB$8),country!$G:$CD,$A19,FALSE)/1000000,"..") -> 176098.63 | AC19: =IFERROR(AB19/C19-1,"..") -> -0.15356508
A20: 14 | B20: Hydropower energy | C20: =IFERROR(VLOOKUP(CONCATENATE($C$4,".",C$8),country!$G:$CD,$A20,FALSE)/1000000,"..") -> 12104.577 | D20: =IFERROR(VLOOKUP(CONCATENATE($C$4,".",D$8),country!$G:$CD,$A20,FALSE)/1000000,"..") -> 10309.927 | E20: =IFERROR(VLOOKUP(CONCATENATE($C$4,".",E$8),country!$G:$CD,$A20,FALSE)/1000000,"..") -> 12640.594 | F20: =IFERROR(VLOOKUP(CONCATENATE($C$4,".",F$8),country!$G:$CD,$A20,FALSE)/1000000,"..") -> 11927.848 | G20: =IFERROR(VLOOKUP(CONCATENATE($C$4,".",G$8),country!$G:$CD,$A20,FALSE)/1000000,"..") -> 9719.6352 | H20: =IFERROR(VLOOKUP(CONCATENATE($C$4,".",H$8),country!$G:$CD,$A20,FALSE)/1000000,"..") -> 13064.207 | I20: =IFERROR(VLOOKUP(CONCATENATE($C$4,".",I$8),country!$G:$CD,$A20,FALSE)/1000000,"..") -> 16831.348 | J20: =IFERROR(VLOOKUP(CONCATENATE($C$4,".",J$8),country!$G:$CD,$A20,FALSE)/1000000,"..") -> 16294.099 | ... AB20: =IFERROR(VLOOKUP(CONCATENATE($C$4,".",AB$8),country!$G:$CD,$A20,FALSE)/1000000,"..") -> 12132.576 | AC20: =IFERROR(AB20/C20-1,"..") -> 0.0023131473
... A28: 2 | B28: Population (millions) | C28: =IFERROR(VLOOKUP(CONCATENATE($C$4,".",C$8),country!$G:$CD,$A28,FALSE)/1000000,"..") -> 34.94611 | D28: =IFERROR(VLOOKUP(CONCATENATE($C$4,".",D$8),country!$G:$CD,$A28,FALSE)/1000000,"..") -> 35.389362 | E28: =IFERROR(VLOOKUP(CONCATENATE($C$4,".",E$8),country!$G:$CD,$A28,FALSE)/1000000,"..") -> 35.815971 | F28: =IFERROR(VLOOKUP(CONCATENATE($C$4,".",F$8),country!$G:$CD,$A28,FALSE)/1000000,"..") -> 36.233195 | G28: =IFERROR(VLOOKUP(CONCATENATE($C$4,".",G$8),country!$G:$CD,$A28,FALSE)/1000000,"..") -> 36.653031 | H28: =IFERROR(VLOOKUP(CONCATENATE($C$4,".",H$8),country!$G:$CD,$A28,FALSE)/1000000,"..") -> 37.070774 | I28: =IFERROR(VLOOKUP(CONCATENATE($C$4,".",I$8),country!$G:$CD,$A28,FALSE)/1000000,"..") -> 37.480493 | J28: =IFERROR(VLOOKUP(CONCATENATE($C$4,".",J$8),country!$G:$CD,$A28,FALSE)/1000000,"..") -> 37.885028 | ... AB28: =IFERROR(VLOOKUP(CONCATENATE($C$4,".",AB$8),country!$G:$CD,$A28,FALSE)/1000000,"..") -> 45.376763 | AC28: =IFERROR(AB28/C28-1,"..") -> 0.29847823
B30: Per Capita, chained 2019 USD | C30: 1995 | D30: 1996 | E30: 1997 | F30: 1998 | G30: 1999 | H30: 2000 | I30: 2001 | J30: 2002 | K30: 2003 | L30: 2004 | M30: 2005 | N30: 2006 | O30: 2007 | P30: 2008 | Q30: 2009 | R30: 2010 | S30: 2011 | T30: 2012 | U30: 2013 | V30: 2014 | W30: 2015 | X30: 2016 | Y30: 2017 | Z30: 2018 | AA30: 2019 | AB30: 2020 | AC30: Percent change (1995 to 2020)
B31: National comprehensive wealth index | C31: =IFERROR(C9/C$28,"..") -> 50817.262 | D31: =IFERROR(D9/D$28,"..") -> 49602.113 | E31: =IFERROR(E9/E$28,"..") -> 47973.063 | F31: =IFERROR(F9/F$28,"..") -> 47712.016 | G31: =IFERROR(G9/G$28,"..") -> 45100.255 | H31: =IFERROR(H9/H$28,"..") -> 44633.189 | I31: =IFERROR(I9/I$28,"..") -> 41034.095 | J31: =IFERROR(J9/J$28,"..") -> 52890.447 | ... AB31: =IFERROR(AB9/AB$28,"..") -> 82996.827 | AC31: =IFERROR(AB31/C31-1,"..") -> 0.63324081
B32: Produced capital | C32: =IFERROR(C10/C$28,"..") -> 11194.323 | D32: =IFERROR(D10/D$28,"..") -> 11445.93 | E32: =IFERROR(E10/E$28,"..") -> 11816.289 | F32: =IFERROR(F10/F$28,"..") -> 12215.946 | G32: =IFERROR(G10/G$28,"..") -> 12459.503 | H32: =IFERROR(H10/H$28,"..") -> 12627.974 | I32: =IFERROR(I10/I$28,"..") -> 12667.196 | J32: =IFERROR(J10/J$28,"..") -> 12454.633 | ... AB32: =IFERROR(AB10/AB$28,"..") -> 18241.585 | AC32: =IFERROR(AB32/C32-1,"..") -> 0.62953882
B33: Human capital | C33: =IFERROR(C11/C$28,"..") -> 41640.895 | D33: =IFERROR(D11/D$28,"..") -> 43133.749 | E33: =IFERROR(E11/E$28,"..") -> 45158.964 | F33: =IFERROR(F11/F$28,"..") -> 46849.938 | G33: =IFERROR(G11/G$28,"..") -> 45969.39 | H33: =IFERROR(H11/H$28,"..") -> 45544.256 | I33: =IFERROR(I11/I$28,"..") -> 44420.989 | J33: =IFERROR(J11/J$28,"..") -> 42665.249 | ... AB33: =IFERROR(AB11/AB$28,"..") -> 56586.551 | AC33: =IFERROR(AB33/C33-1,"..") -> 0.35891772
B34: Renewable natural capital | C34: =IFERROR(C12/C$28,"..") -> 9367.0189 | D34: =IFERROR(D12/D$28,"..") -> 9023.5058 | E34: =IFERROR(E12/E$28,"..") -> 9114.8111 | F34: =IFERROR(F12/F$28,"..") -> 8904.45 | G34: =IFERROR(G12/G$28,"..") -> 8566.7103 | H34: =IFERROR(H12/H$28,"..") -> 8765.8409 | I34: =IFERROR(I12/I$28,"..") -> 9105.1455 | J34: =IFERROR(J12/J$28,"..") -> 8935.8633 | ... AB34: =IFERROR(AB12/AB$28,"..") -> 6303.9313 | AC34: =IFERROR(AB34/C34-1,"..") -> -0.32700773
B35: Forests, timber | C35: =IFERROR(C13/C$28,"..") -> 568.95861 | D35: =IFERROR(D13/D$28,"..") -> 558.84064 | E35: =IFERROR(E13/E$28,"..") -> 549.22808 | F35: =IFERROR(F13/F$28,"..") -> 539.98165 | G35: =IFERROR(G13/G$28,"..") -> 530.9079 | H35: =IFERROR(H13/H$28,"..") -> 522.06914 | I35: =IFERROR(I13/I$28,"..") -> 511.46737 | J35: =IFERROR(J13/J$28,"..") -> 501.16346 | ... AB35: =IFERROR(AB13/AB$28,"..") -> 365.10829 | AC35: =IFERROR(AB35/C35-1,"..") -> -0.35828673
B36: Forests, recreation, hunting, and fishing services (es1) | C36: =IFERROR(C14/C$28,"..") -> 142.20628 | D36: =IFERROR(D14/D$28,"..") -> 139.67738 | E36: =IFERROR(E14/E$28,"..") -> 137.2748 | F36: =IFERROR(F14/F$28,"..") -> 134.96374 | G36: =IFERROR(G14/G$28,"..") -> 132.69583 | H36: =IFERROR(H14/H$28,"..") -> 130.48666 | I36: =IFERROR(I14/I$28,"..") -> 127.83684 | J36: =IFERROR(J14/J$28,"..") -> 125.26147 | ... AB36: =IFERROR(AB14/AB$28,"..") -> 91.255655 | AC36: =IFERROR(AB36/C36-1,"..") -> -0.35828673
B37: Forests, non-wood forest products (es2) | C37: =IFERROR(C15/C$28,"..") -> 263.00417 | D37: =IFERROR(D15/D$28,"..") -> 258.32708 | E37: =IFERROR(E15/E$28,"..") -> 253.88362 | F37: =IFERROR(F15/F$28,"..") -> 249.60941 | G37: =IFERROR(G15/G$28,"..") -> 245.41502 | H37: =IFERROR(H15/H$28,"..") -> 241.32926 | I37: =IFERROR(I15/I$28,"..") -> 236.42854 | J37: =IFERROR(J15/J$28,"..") -> 231.6655 | ... AB37: =IFERROR(AB15/AB$28,"..") -> 168.77326 | AC37: =IFERROR(AB37/C37-1,"..") -> -0.35828673
B38: Forests, water retention services (es3) | C38: =IFERROR(C16/C$28,"..") -> 2241.9864 | D38: =IFERROR(D16/D$28,"..") -> 2202.1164 | E38: =IFERROR(E16/E$28,"..") -> 2164.2381 | F38: =IFERROR(F16/F$28,"..") -> 2127.8024 | G38: =IFERROR(G16/G$28,"..") -> 2092.0472 | H38: =IFERROR(H16/H$28,"..") -> 2057.218 | I38: =IFERROR(I16/I$28,"..") -> 2015.4417 | J38: =IFERROR(J16/J$28,"..") -> 1974.839 | ... AB38: =IFERROR(AB16/AB$28,"..") -> 1438.7124 | AC38: =IFERROR(AB38/C38-1,"..") -> -0.35828673
B39: Mangroves | C39: =IFERROR(C17/C$28,"..") -> 0 | D39: =IFERROR(D17/D$28,"..") -> 0 | E39: =IFERROR(E17/E$28,"..") -> 0 | F39: =IFERROR(F17/F$28,"..") -> 0 | G39: =IFERROR(G17/G$28,"..") -> 0 | H39: =IFERROR(H17/H$28,"..") -> 0 | I39: =IFERROR(I17/I$28,"..") -> 0 | J39: =IFERROR(J17/J$28,"..") -> 0 | ... AB39: =IFERROR(AB17/AB$28,"..") -> 0 | AC39: =IFERROR(AB39/C39-1,"..") -> ..
B40: Fisheries | C40: =IFERROR(C18/C$28,"..") -> 74.836873 | D40: =IFERROR(D18/D$28,"..") -> 71.746951 | E40: =IFERROR(E18/E$28,"..") -> 68.443805 | F40: =IFERROR(F18/F$28,"..") -> 65.467976 | G40: =IFERROR(G18/G$28,"..") -> 62.807147 | H40: =IFERROR(H18/H$28,"..") -> 60.580756 | I40: =IFERROR(I18/I$28,"..") -> 59.269147 | J40: =IFERROR(J18/J$28,"..") -> 58.447301 | ... AB40: =IFERROR(AB18/AB$28,"..") -> 54.000638 | AC40: =IFERROR(AB40/C40-1,"..") -> -0.27842204
B41: Agricultural land | C41: =IFERROR(C19/C$28,"..") -> 5953.3796 | D41: =IFERROR(D19/D$28,"..") -> 5883.2669 | E41: =IFERROR(E19/E$28,"..") -> 5817.4095 | F41: =IFERROR(F19/F$28,"..") -> 5754.6823 | G41: =IFERROR(G19/G$28,"..") -> 5692.4012 | H41: =IFERROR(H19/H$28,"..") -> 5632.55 | I41: =IFERROR(I19/I$28,"..") -> 5575.1393 | J41: =IFERROR(J19/J$28,"..") -> 5520.0685 | ... AB41: =IFERROR(AB19/AB$28,"..") -> 3880.8108 | AC41: =IFERROR(AB41/C41-1,"..") -> -0.34813314
B42: Hydropower energy | C42: =IFERROR(C20/C$28,"..") -> 346.37837 | D42: =IFERROR(D20/D$28,"..") -> 291.32843 | E42: =IFERROR(E20/E$28,"..") -> 352.93178 | F42: =IFERROR(F20/F$28,"..") -> 329.19669 | G42: =IFERROR(G20/G$28,"..") -> 265.17957 | H42: =IFERROR(H20/H$28,"..") -> 352.41256 | I42: =IFERROR(I20/I$28,"..") -> 449.06956 | J42: =IFERROR(J20/J$28,"..") -> 430.09337 | ... AB42: =IFERROR(AB20/AB$28,"..") -> 267.37422 | AC42: =IFERROR(AB42/C42-1,"..") -> -0.22808629
... B49: Foreign liabilities | C49: =IFERROR(C27/C$28,"..") -> 29297.558 | D49: =IFERROR(D27/D$28,"..") -> 32932.664 | E49: =IFERROR(E27/E$28,"..") -> 38198.571 | F49: =IFERROR(F27/F$28,"..") -> 41096.544 | G49: =IFERROR(G27/G$28,"..") -> 43532.217 | H49: =IFERROR(H27/H$28,"..") -> 44010.048 | I49: =IFERROR(I27/I$28,"..") -> 45860.425 | J49: =IFERROR(J27/J$28,"..") -> 29311.499 | ... AB49: =IFERROR(AB27/AB$28,"..") -> 4309.1405 | AC49: =IFERROR(AB49/C49-1,"..") -> -0.8529181
B55: Nominal Wealth, current USD, Millions | C55: 1995 | D55: 1996 | E55: 1997 | F55: 1998 | G55: 1999 | H55: 2000 | I55: 2001 | J55: 2002 | K55: 2003 | L55: 2004 | M55: 2005 | N55: 2006 | O55: 2007 | P55: 2008 | Q55: 2009 | R55: 2010 | S55: 2011 | T55: 2012 | U55: 2013 | V55: 2014 | W55: 2015 | X55: 2016 | Y55: 2017 | Z55: 2018 | AA55: 2019 | AB55: 2020 | AC55: Percent change (1995 to 2020)
A56: 38 | B56: Produced capital | C56: =IFERROR(VLOOKUP(CONCATENATE($C$4,".",C$8),country!$G:$CD,$A56,FALSE)/1000000,"..") -> 564923.39 | D56: =IFERROR(VLOOKUP(CONCATENATE($C$4,".",D$8),country!$G:$CD,$A56,FALSE)/1000000,"..") -> 536423.53 | E56: =IFERROR(VLOOKUP(CONCATENATE($C$4,".",E$8),country!$G:$CD,$A56,FALSE)/1000000,"..") -> 545420.09 | F56: =IFERROR(VLOOKUP(CONCATENATE($C$4,".",F$8),country!$G:$CD,$A56,FALSE)/1000000,"..") -> 568948.96 | G56: =IFERROR(VLOOKUP(CONCATENATE($C$4,".",G$8),country!$G:$CD,$A56,FALSE)/1000000,"..") -> 594111.46 | H56: =IFERROR(VLOOKUP(CONCATENATE($C$4,".",H$8),country!$G:$CD,$A56,FALSE)/1000000,"..") -> 608102.32 | I56: =IFERROR(VLOOKUP(CONCATENATE($C$4,".",I$8),country!$G:$CD,$A56,FALSE)/1000000,"..") -> 622997.8 | J56: =IFERROR(VLOOKUP(CONCATENATE($C$4,".",J$8),country!$G:$CD,$A56,FALSE)/1000000,"..") -> 299800.76 | ... AB56: =IFERROR(VLOOKUP(CONCATENATE($C$4,".",AB$8),country!$G:$CD,$A56,FALSE)/1000000,"..") -> 847346.99 | AC56: =IFERROR(AB56/C56-1,"..") -> 0.49993258
A57: 72 | B57: Human capital | C57: =IFERROR(VLOOKUP(CONCATENATE($C$4,".",C$8),country!$G:$CD,$A57,FALSE)/1000000,"..") -> 1009371.3 | D57: =IFERROR(VLOOKUP(CONCATENATE($C$4,".",D$8),country!$G:$CD,$A57,FALSE)/1000000,"..") -> 1023125.9 | E57: =IFERROR(VLOOKUP(CONCATENATE($C$4,".",E$8),country!$G:$CD,$A57,FALSE)/1000000,"..") -> 1120110.7 | F57: =IFERROR(VLOOKUP(CONCATENATE($C$4,".",F$8),country!$G:$CD,$A57,FALSE)/1000000,"..") -> 1237128.2 | G57: =IFERROR(VLOOKUP(CONCATENATE($C$4,".",G$8),country!$G:$CD,$A57,FALSE)/1000000,"..") -> 1243042.4 | H57: =IFERROR(VLOOKUP(CONCATENATE($C$4,".",H$8),country!$G:$CD,$A57,FALSE)/1000000,"..") -> 1298501.5 | I57: =IFERROR(VLOOKUP(CONCATENATE($C$4,".",I$8),country!$G:$CD,$A57,FALSE)/1000000,"..") -> 1267899.3 | J57: =IFERROR(VLOOKUP(CONCATENATE($C$4,".",J$8),country!$G:$CD,$A57,FALSE)/1000000,"..") -> 362791.22 | ... AB57: =IFERROR(VLOOKUP(CONCATENATE($C$4,".",AB$8),country!$G:$CD,$A57,FALSE)/1000000,"..") -> 2029767.7 | AC57: =IFERROR(AB57/C57-1,"..") -> 1.0109227
A58: 43 | B58: Renewable natural capital | C58: =IFERROR(VLOOKUP(CONCATENATE($C$4,".",C$8),country!$G:$CD,$A58,FALSE)/1000000,"..") -> 201992.04 | D58: =IFERROR(VLOOKUP(CONCATENATE($C$4,".",D$8),country!$G:$CD,$A58,FALSE)/1000000,"..") -> 193919.49 | E58: =IFERROR(VLOOKUP(CONCATENATE($C$4,".",E$8),country!$G:$CD,$A58,FALSE)/1000000,"..") -> 208521.59 | F58: =IFERROR(VLOOKUP(CONCATENATE($C$4,".",F$8),country!$G:$CD,$A58,FALSE)/1000000,"..") -> 201196.21 | G58: =IFERROR(VLOOKUP(CONCATENATE($C$4,".",G$8),country!$G:$CD,$A58,FALSE)/1000000,"..") -> 177817.31 | H58: =IFERROR(VLOOKUP(CONCATENATE($C$4,".",H$8),country!$G:$CD,$A58,FALSE)/1000000,"..") -> 192911.49 | I58: =IFERROR(VLOOKUP(CONCATENATE($C$4,".",I$8),country!$G:$CD,$A58,FALSE)/1000000,"..") -> 178083.11 | J58: =IFERROR(VLOOKUP(CONCATENATE($C$4,".",J$8),country!$G:$CD,$A58,FALSE)/1000000,"..") -> 99794.43 | ... AB58: =IFERROR(VLOOKUP(CONCATENATE($C$4,".",AB$8),country!$G:$CD,$A58,FALSE)/1000000,"..") -> 263120.63 | AC58: =IFERROR(AB58/C58-1,"..") -> 0.3026287
A59: 47 | B59: Forests, timber | C59: =IFERROR(VLOOKUP(CONCATENATE($C$4,".",C$8),country!$G:$CD,$A59,FALSE)/1000000,"..") -> 6116.99 | D59: =IFERROR(VLOOKUP(CONCATENATE($C$4,".",D$8),country!$G:$CD,$A59,FALSE)/1000000,"..") -> 5652.7735 | E59: =IFERROR(VLOOKUP(CONCATENATE($C$4,".",E$8),country!$G:$CD,$A59,FALSE)/1000000,"..") -> 4775.9178 | F59: =IFERROR(VLOOKUP(CONCATENATE($C$4,".",F$8),country!$G:$CD,$A59,FALSE)/1000000,"..") -> 4381.5843 | G59: =IFERROR(VLOOKUP(CONCATENATE($C$4,".",G$8),country!$G:$CD,$A59,FALSE)/1000000,"..") -> 3522.4437 | H59: =IFERROR(VLOOKUP(CONCATENATE($C$4,".",H$8),country!$G:$CD,$A59,FALSE)/1000000,"..") -> 2789.3785 | I59: =IFERROR(VLOOKUP(CONCATENATE($C$4,".",I$8),country!$G:$CD,$A59,FALSE)/1000000,"..") -> 2577.9761 | J59: =IFERROR(VLOOKUP(CONCATENATE($C$4,".",J$8),country!$G:$CD,$A59,FALSE)/1000000,"..") -> 4698.6826 | ... AB59: =IFERROR(VLOOKUP(CONCATENATE($C$4,".",AB$8),country!$G:$CD,$A59,FALSE)/1000000,"..") -> 16886.694 | AC59: =IFERROR(AB59/C59-1,"..") -> 1.7606214
A60: 49 | B60: Forests, recreation, hunting, and fishing services (es1) | C60: =IFERROR(VLOOKUP(CONCATENATE($C$4,".",C$8),country!$G:$CD,$A60,FALSE)/1000000,"..") -> 1874.6324 | D60: =IFERROR(VLOOKUP(CONCATENATE($C$4,".",D$8),country!$G:$CD,$A60,FALSE)/1000000,"..") -> 2187.0712 | E60: =IFERROR(VLOOKUP(CONCATENATE($C$4,".",E$8),country!$G:$CD,$A60,FALSE)/1000000,"..") -> 2317.9279 | F60: =IFERROR(VLOOKUP(CONCATENATE($C$4,".",F$8),country!$G:$CD,$A60,FALSE)/1000000,"..") -> 2464.9578 | G60: =IFERROR(VLOOKUP(CONCATENATE($C$4,".",G$8),country!$G:$CD,$A60,FALSE)/1000000,"..") -> 2334.1012 | H60: =IFERROR(VLOOKUP(CONCATENATE($C$4,".",H$8),country!$G:$CD,$A60,FALSE)/1000000,"..") -> 2348.8042 | I60: =IFERROR(VLOOKUP(CONCATENATE($C$4,".",I$8),country!$G:$CD,$A60,FALSE)/1000000,"..") -> 2026.0733 | J60: =IFERROR(VLOOKUP(CONCATENATE($C$4,".",J$8),country!$G:$CD,$A60,FALSE)/1000000,"..") -> 1261.5173 | ... AB60: =IFERROR(VLOOKUP(CONCATENATE($C$4,".",AB$8),country!$G:$CD,$A60,FALSE)/1000000,"..") -> 1251.2252 | AC60: =IFERROR(AB60/C60-1,"..") -> -0.33254902
A61: 50 | B61: Forests, non-wood forest products (es2) | C61: =IFERROR(VLOOKUP(CONCATENATE($C$4,".",C$8),country!$G:$CD,$A61,FALSE)/1000000,"..") -> 6599.2944 | D61: =IFERROR(VLOOKUP(CONCATENATE($C$4,".",D$8),country!$G:$CD,$A61,FALSE)/1000000,"..") -> 6682.949 | E61: =IFERROR(VLOOKUP(CONCATENATE($C$4,".",E$8),country!$G:$CD,$A61,FALSE)/1000000,"..") -> 6772.879 | F61: =IFERROR(VLOOKUP(CONCATENATE($C$4,".",F$8),country!$G:$CD,$A61,FALSE)/1000000,"..") -> 6820.5783 | G61: =IFERROR(VLOOKUP(CONCATENATE($C$4,".",G$8),country!$G:$CD,$A61,FALSE)/1000000,"..") -> 6902.3993 | H61: =IFERROR(VLOOKUP(CONCATENATE($C$4,".",H$8),country!$G:$CD,$A61,FALSE)/1000000,"..") -> 7049.4561 | I61: =IFERROR(VLOOKUP(CONCATENATE($C$4,".",I$8),country!$G:$CD,$A61,FALSE)/1000000,"..") -> 7006.0894 | J61: =IFERROR(VLOOKUP(CONCATENATE($C$4,".",J$8),country!$G:$CD,$A61,FALSE)/1000000,"..") -> 6850.691 | ... AB61: =IFERROR(VLOOKUP(CONCATENATE($C$4,".",AB$8),country!$G:$CD,$A61,FALSE)/1000000,"..") -> 7748.3836 | AC61: =IFERROR(AB61/C61-1,"..") -> 0.17412305
...

Sheet Wealth_graphs
A1: IMPORTANT NOTE: | B1: The trends in total wealth and asset categories (produced, human, renewable, and nonrenewable natural capital) are based on the Törnqvist index, where the change in physical volumes of individual assets is weighted by their value shares. “Volume” here refers to the physical quantity of each asset, or a proxy for that quantity. For example, the volume of timber assets is measured in hectares, while the volume of oil assets is measured in barrels. Because these assets are measured in different units, the Törnqvist index allows us to combine them by weighting the change in each asset by its value share, making the changes unitless and allowing the aggregation of different asset types to obtain an overall measure of how the total volume has changed. The Törnqvist volume index it is 'chained' together to make a time series by selecting a base year (2019) and then expressing other years in terms relative to the base year. For the base year, the chained Törnqvist volume index is normalized to 100. To make the index easier to interpret, the chained volume index is converted into monetary terms using 2019 US dollars, referred to as real asset values and expressed in “chained 2019 dollars”. This adjustment captures the "real" value of assets while removing the effect of inflation and other price changes. For each individual asset (sub-components of the aggregate categories), the change between 1995 and 2020 follows the trend in physical volumes, but unlike the aggregate asset categories, the changes over time in individual assets are not weighted by their shares in total wealth.
A3: ='Select a Country'!B4 -> Argentina
A5: Millions, chained 2019 USD | B5: 1995 | C5: 1996 | D5: 1997 | E5: 1998 | F5: 1999 | G5: 2000 | H5: 2001 | I5: 2002 | J5: 2003 | K5: 2004 | L5: 2005 | M5: 2006 | N5: 2007 | O5: 2008 | P5: 2009 | Q5: 2010 | R5: 2011 | S5: 2012 | T5: 2013 | U5: 2014 | V5: 2015 | W5: 2016 | X5: 2017 | Y5: 2018 | Z5: 2019 | AA5: 2020
A6: National Comprehensive Wealth Index | B6: ='Select a Country'!C9 -> 1775865.6 | C6: ='Select a Country'!D9 -> 1755387.1 | D6: ='Select a Country'!E9 -> 1718201.8 | E6: ='Select a Country'!F9 -> 1728758.8 | F6: ='Select a Country'!G9 -> 1653061 | G6: ='Select a Country'!H9 -> 1654586.9 | H6: ='Select a Country'!I9 -> 1537978.1 | I6: ='Select a Country'!J9 -> 2003756.1 | ... AA6: ='Select a Country'!AB9 -> 3766127.3
A7: Produced Capital | B7: ='Select a Country'!C10 -> 391198.06 | C7: ='Select a Country'!D10 -> 405064.18 | D7: ='Select a Country'!E10 -> 423211.87 | E7: ='Select a Country'!F10 -> 442622.75 | F7: ='Select a Country'!G10 -> 456678.56 | G7: ='Select a Country'!H10 -> 468128.76 | H7: ='Select a Country'!I10 -> 474772.76 | I7: ='Select a Country'!J10 -> 471844.11 | ... AA7: ='Select a Country'!AB10 -> 827744.06
A8: Human Capital | B8: ='Select a Country'!C11 -> 1455187.3 | C8: ='Select a Country'!D11 -> 1526475.9 | D8: ='Select a Country'!E11 -> 1617412.2 | E8: ='Select a Country'!F11 -> 1697522.9 | F8: ='Select a Country'!G11 -> 1684917.5 | G8: ='Select a Country'!H11 -> 1688360.8 | H8: ='Select a Country'!I11 -> 1664920.6 | I8: ='Select a Country'!J11 -> 1616374.1 | ... AA8: ='Select a Country'!AB11 -> 2567714.5
A9: Renewable Natural Capital | B9: =SUM('Select a Country'!C12) -> 327340.87 | C9: =SUM('Select a Country'!D12) -> 319336.11 | D9: =SUM('Select a Country'!E12) -> 326455.81 | E9: =SUM('Select a Country'!F12) -> 322636.67 | F9: =SUM('Select a Country'!G12) -> 313995.9 | G9: =SUM('Select a Country'!H12) -> 324956.51 | H9: =SUM('Select a Country'!I12) -> 341265.34 | I9: =SUM('Select a Country'!J12) -> 338535.43 | ... AA9: =SUM('Select a Country'!AB12) -> 286052
A10: Nonrenewable Natural Capital | B10: ='Select a Country'!C21 -> 78911.938 | C10: ='Select a Country'!D21 -> 84836.893 | D10: ='Select a Country'!E21 -> 86648.798 | E10: ='Select a Country'!F21 -> 89583.474 | F10: ='Select a Country'!G21 -> 97870.369 | G10: ='Select a Country'!H21 -> 97810.516 | H10: ='Select a Country'!I21 -> 95128.032 | I10: ='Select a Country'!J21 -> 89471.797 | ... AA10: ='Select a Country'!AB21 -> 32635.538
A11: Foreign Assets | B11: ='Select a Country'!C26 -> 773697.88 | C11: ='Select a Country'!D26 -> 888926.35 | D11: ='Select a Country'!E26 -> 1020923.4 | E11: ='Select a Country'!F26 -> 1076835 | F11: ='Select a Country'!G26 -> 1181432.8 | G11: ='Select a Country'!H26 -> 1197848.5 | H11: ='Select a Country'!I26 -> 1060027.5 | I11: ='Select a Country'!J26 -> 827758.74 | ... AA11: ='Select a Country'!AB26 -> 278419.7
A12: Foreign Liabilities | B12: ='Select a Country'!C27 -> 1023835.7 | C12: ='Select a Country'!D27 -> 1165466 | D12: ='Select a Country'!E27 -> 1368118.9 | E12: ='Select a Country'!F27 -> 1489059.1 | F12: ='Select a Country'!G27 -> 1595587.7 | G12: ='Select a Country'!H27 -> 1631486.5 | H12: ='Select a Country'!I27 -> 1718871.3 | I12: ='Select a Country'!J27 -> 1110467 | ... AA12: ='Select a Country'!AB27 -> 195534.85
A13: Population (millions) | B13: ='Select a Country'!C28 -> 34.94611 | C13: ='Select a Country'!D28 -> 35.389362 | D13: ='Select a Country'!E28 -> 35.815971 | E13: ='Select a Country'!F28 -> 36.233195 | F13: ='Select a Country'!G28 -> 36.653031 | G13: ='Select a Country'!H28 -> 37.070774 | H13: ='Select a Country'!I28 -> 37.480493 | I13: ='Select a Country'!J28 -> 37.885028 | ... AA13: ='Select a Country'!AB28 -> 45.376763
A15: =CONCATENATE("Real Wealth Per Capita, 1995 - 2020, ",$A$3) -> Real Wealth Per Capita, 1995 - 2020, Argentina
A16: Per Capita, chained 2019 USD | B16: 1995 | C16: 1996 | D16: 1997 | E16: 1998 | F16: 1999 | G16: 2000 | H16: 2001 | I16: 2002 | J16: 2003 | K16: 2004 | L16: 2005 | M16: 2006 | N16: 2007 | O16: 2008 | P16: 2009 | Q16: 2010 | R16: 2011 | S16: 2012 | T16: 2013 | U16: 2014 | V16: 2015 | W16: 2016 | X16: 2017 | Y16: 2018 | Z16: 2019 | AA16: 2020
A17: National Comprehensive Wealth Index | B17: =IF(IFERROR(B6/B$13, "..")=0, NA(), IFERROR(B6/B$13, "..")) -> 50817.262 | C17: =IF(IFERROR(C6/C$13, "..")=0, NA(), IFERROR(C6/C$13, "..")) -> 49602.113 | D17: =IF(IFERROR(D6/D$13, "..")=0, NA(), IFERROR(D6/D$13, "..")) -> 47973.063 | E17: =IF(IFERROR(E6/E$13, "..")=0, NA(), IFERROR(E6/E$13, "..")) -> 47712.016 | F17: =IF(IFERROR(F6/F$13, "..")=0, NA(), IFERROR(F6/F$13, "..")) -> 45100.255 | G17: =IF(IFERROR(G6/G$13, "..")=0, NA(), IFERROR(G6/G$13, "..")) -> 44633.189 | H17: =IF(IFERROR(H6/H$13, "..")=0, NA(), IFERROR(H6/H$13, "..")) -> 41034.095 | I17: =IF(IFERROR(I6/I$13, "..")=0, NA(), IFERROR(I6/I$13, "..")) -> 52890.447 | ... AA17: =IF(IFERROR(AA6/AA$13, "..")=0, NA(), IFERROR(AA6/AA$13, "..")) -> 82996.827
A18: Produced Capital | B18: =IF(IFERROR(B7/B$13, "..")=0, NA(), IFERROR(B7/B$13, "..")) -> 11194.323 | C18: =IF(IFERROR(C7/C$13, "..")=0, NA(), IFERROR(C7/C$13, "..")) -> 11445.93 | D18: =IF(IFERROR(D7/D$13, "..")=0, NA(), IFERROR(D7/D$13, "..")) -> 11816.289 | E18: =IF(IFERROR(E7/E$13, "..")=0, NA(), IFERROR(E7/E$13, "..")) -> 12215.946 | F18: =IF(IFERROR(F7/F$13, "..")=0, NA(), IFERROR(F7/F$13, "..")) -> 12459.503 | G18: =IF(IFERROR(G7/G$13, "..")=0, NA(), IFERROR(G7/G$13, "..")) -> 12627.974 | H18: =IF(IFERROR(H7/H$13, "..")=0, NA(), IFERROR(H7/H$13, "..")) -> 12667.196 | I18: =IF(IFERROR(I7/I$13, "..")=0, NA(), IFERROR(I7/I$13, "..")) -> 12454.633 | ... AA18: =IF(IFERROR(AA7/AA$13, "..")=0, NA(), IFERROR(AA7/AA$13, "..")) -> 18241.585
A19: Human Capital | B19: =IF(IFERROR(B8/B$13, "..")=0, NA(), IFERROR(B8/B$13, "..")) -> 41640.895 | C19: =IF(IFERROR(C8/C$13, "..")=0, NA(), IFERROR(C8/C$13, "..")) -> 43133.749 | D19: =IF(IFERROR(D8/D$13, "..")=0, NA(), IFERROR(D8/D$13, "..")) -> 45158.964 | E19: =IF(IFERROR(E8/E$13, "..")=0, NA(), IFERROR(E8/E$13, "..")) -> 46849.938 | F19: =IF(IFERROR(F8/F$13, "..")=0, NA(), IFERROR(F8/F$13, "..")) -> 45969.39 | G19: =IF(IFERROR(G8/G$13, "..")=0, NA(), IFERROR(G8/G$13, "..")) -> 45544.256 | H19: =IF(IFERROR(H8/H$13, "..")=0, NA(), IFERROR(H8/H$13, "..")) -> 44420.989 | I19: =IF(IFERROR(I8/I$13, "..")=0, NA(), IFERROR(I8/I$13, "..")) -> 42665.249 | ... AA19: =IF(IFERROR(AA8/AA$13, "..")=0, NA(), IFERROR(AA8/AA$13, "..")) -> 56586.551
A20: Renewable Natural Capital | B20: =IF(IFERROR(B9/B$13, "..")=0, NA(), IFERROR(B9/B$13, "..")) -> 9367.0189 | C20: =IF(IFERROR(C9/C$13, "..")=0, NA(), IFERROR(C9/C$13, "..")) -> 9023.5058 | D20: =IF(IFERROR(D9/D$13, "..")=0, NA(), IFERROR(D9/D$13, "..")) -> 9114.8111 | E20: =IF(IFERROR(E9/E$13, "..")=0, NA(), IFERROR(E9/E$13, "..")) -> 8904.45 | F20: =IF(IFERROR(F9/F$13, "..")=0, NA(), IFERROR(F9/F$13, "..")) -> 8566.7103 | G20: =IF(IFERROR(G9/G$13, "..")=0, NA(), IFERROR(G9/G$13, "..")) -> 8765.8409 | H20: =IF(IFERROR(H9/H$13, "..")=0, NA(), IFERROR(H9/H$13, "..")) -> 9105.1455 | I20: =IF(IFERROR(I9/I$13, "..")=0, NA(), IFERROR(I9/I$13, "..")) -> 8935.8633 | ... AA20: =IF(IFERROR(AA9/AA$13, "..")=0, NA(), IFERROR(AA9/AA$13, "..")) -> 6303.9313 | AB20: Note: Renewable includes forests, mangroves, fisheries, agricultural land and hydropower energy.
A21: Nonrenewable Natural Capital | B21: =IF(IFERROR(B10/B$13, "..")=0, NA(), IFERROR(B10/B$13, "..")) -> 2258.1036 | C21: =IF(IFERROR(C10/C$13, "..")=0, NA(), IFERROR(C10/C$13, "..")) -> 2397.2428 | D21: =IF(IFERROR(D10/D$13, "..")=0, NA(), IFERROR(D10/D$13, "..")) -> 2419.2782 | E21: =IF(IFERROR(E10/E$13, "..")=0, NA(), IFERROR(E10/E$13, "..")) -> 2472.4144 | F21: =IF(IFERROR(F10/F$13, "..")=0, NA(), IFERROR(F10/F$13, "..")) -> 2670.1849 | G21: =IF(IFERROR(G10/G$13, "..")=0, NA(), IFERROR(G10/G$13, "..")) -> 2638.4805 | H21: =IF(IFERROR(H10/H$13, "..")=0, NA(), IFERROR(H10/H$13, "..")) -> 2538.0678 | I21: =IF(IFERROR(I10/I$13, "..")=0, NA(), IFERROR(I10/I$13, "..")) -> 2361.6664 | ... AA21: =IF(IFERROR(AA10/AA$13, "..")=0, NA(), IFERROR(AA10/AA$13, "..")) -> 719.21256 | AB21: Note: Nonrenewable refers to subsoil assets (oil, gas, coal, metals and minerals).
A22: Foreign Assets | B22: =IF(IFERROR(B11/B$13, "..")=0, NA(), IFERROR(B11/B$13, "..")) -> 22139.742 | C22: =IF(IFERROR(C11/C$13, "..")=0, NA(), IFERROR(C11/C$13, "..")) -> 25118.462 | D22: =IF(IFERROR(D11/D$13, "..")=0, NA(), IFERROR(D11/D$13, "..")) -> 28504.698 | E22: =IF(IFERROR(E11/E$13, "..")=0, NA(), IFERROR(E11/E$13, "..")) -> 29719.57 | F22: =IF(IFERROR(F11/F$13, "..")=0, NA(), IFERROR(F11/F$13, "..")) -> 32232.883 | G22: =IF(IFERROR(G11/G$13, "..")=0, NA(), IFERROR(G11/G$13, "..")) -> 32312.475 | H22: =IF(IFERROR(H11/H$13, "..")=0, NA(), IFERROR(H11/H$13, "..")) -> 28282.112 | I22: =IF(IFERROR(I11/I$13, "..")=0, NA(), IFERROR(I11/I$13, "..")) -> 21849.231 | ... AA22: =IF(IFERROR(AA11/AA$13, "..")=0, NA(), IFERROR(AA11/AA$13, "..")) -> 6135.7329
A23: Foreign Liablities | B23: =IF(IFERROR(B12/B$13, "..")=0, NA(), IFERROR(B12/B$13, "..")) -> 29297.558 | C23: =IF(IFERROR(C12/C$13, "..")=0, NA(), IFERROR(C12/C$13, "..")) -> 32932.664 | D23: =IF(IFERROR(D12/D$13, "..")=0, NA(), IFERROR(D12/D$13, "..")) -> 38198.571 | E23: =IF(IFERROR(E12/E$13, "..")=0, NA(), IFERROR(E12/E$13, "..")) -> 41096.544 | F23: =IF(IFERROR(F12/F$13, "..")=0, NA(), IFERROR(F12/F$13, "..")) -> 43532.217 | G23: =IF(IFERROR(G12/G$13, "..")=0, NA(), IFERROR(G12/G$13, "..")) -> 44010.048 | H23: =IF(IFERROR(H12/H$13, "..")=0, NA(), IFERROR(H12/H$13, "..")) -> 45860.425 | I23: =IF(IFERROR(I12/I$13, "..")=0, NA(), IFERROR(I12/I$13, "..")) -> 29311.499 | ... AA23: =IF(IFERROR(AA12/AA$13, "..")=0, NA(), IFERROR(AA12/AA$13, "..")) -> 4309.1405
A25: =CONCATENATE("Trends in real Wealth Per Capita, 1995 - 2020, ",$A$3) -> Trends in real Wealth Per Capita, 1995 - 2020, Argentina
A26: Per Capita, chained 2019 USD, Indexed | B26: 1995 | C26: 1996 | D26: 1997 | E26: 1998 | F26: 1999 | G26: 2000 | H26: 2001 | I26: 2002 | J26: 2003 | K26: 2004 | L26: 2005 | M26: 2006 | N26: 2007 | O26: 2008 | P26: 2009 | Q26: 2010 | R26: 2011 | S26: 2012 | T26: 2013 | U26: 2014 | V26: 2015 | W26: 2016 | X26: 2017 | Y26: 2018 | Z26: 2019 | AA26: 2020
A27: National Comprehensive Wealth Index | B27: =IF(B17=0, NA(), 100) -> 100 | C27: {=IF(AND(C17=0, ISNA(B27)), NA(), IF(AND(C17<>0, ISNA(B27)), 100, C17/INDEX($B17:$AA17, MATCH(TRUE, $B17:$AA17 <> 0, 0))*100))} -> 97.608786 | D27: {=IF(AND(D17=0, ISNA(C27)), NA(), IF(AND(D17<>0, ISNA(C27)), 100, D17/INDEX($B17:$AA17, MATCH(TRUE, $B17:$AA17 <> 0, 0))*100))} -> 94.403083 | E27: {=IF(AND(E17=0, ISNA(D27)), NA(), IF(AND(E17<>0, ISNA(D27)), 100, E17/INDEX($B17:$AA17, MATCH(TRUE, $B17:$AA17 <> 0, 0))*100))} -> 93.889386 | F27: {=IF(AND(F17=0, ISNA(E27)), NA(), IF(AND(F17<>0, ISNA(E27)), 100, F17/INDEX($B17:$AA17, MATCH(TRUE, $B17:$AA17 <> 0, 0))*100))} -> 88.749872 | G27: {=IF(AND(G17=0, ISNA(F27)), NA(), IF(AND(G17<>0, ISNA(F27)), 100, G17/INDEX($B17:$AA17, MATCH(TRUE, $B17:$AA17 <> 0, 0))*100))} -> 87.830763 | H27: {=IF(AND(H17=0, ISNA(G27)), NA(), IF(AND(H17<>0, ISNA(G27)), 100, H17/INDEX($B17:$AA17, MATCH(TRUE, $B17:$AA17 <> 0, 0))*100))} -> 80.748338 | I27: {=IF(AND(I17=0, ISNA(H27)), NA(), IF(AND(I17<>0, ISNA(H27)), 100, I17/INDEX($B17:$AA17, MATCH(TRUE, $B17:$AA17 <> 0, 0))*100))} -> 104.07969 | J27: {=IF(AND(J17=0, ISNA(I27)), NA(), IF(AND(J17<>0, ISNA(I27)), 100, J17/INDEX($B17:$AA17, MATCH(TRUE, $B17:$AA17 <> 0, 0))*100))} -> 110.78931 | ... AA27: {=IF(AND(AA17=0, ISNA(Z27)), NA(), IF(AND(AA17<>0, ISNA(Z27)), 100, AA17/INDEX($B17:$AA17, MATCH(TRUE, $B17:$AA17 <> 0, 0))*100))} -> 163.32408
A28: Produced Capital | B28: =IF(B18=0, NA(), 100) -> 100 | C28: {=IF(AND(C18=0, ISNA(B28)), NA(), IF(AND(C18<>0, ISNA(B28)), 100, C18/INDEX($B18:$AA18, MATCH(TRUE, $B18:$AA18 <> 0, 0))*100))} -> 102.24763 | D28: {=IF(AND(D18=0, ISNA(C28)), NA(), IF(AND(D18<>0, ISNA(C28)), 100, D18/INDEX($B18:$AA18, MATCH(TRUE, $B18:$AA18 <> 0, 0))*100))} -> 105.55608 | E28: {=IF(AND(E18=0, ISNA(D28)), NA(), IF(AND(E18<>0, ISNA(D28)), 100, E18/INDEX($B18:$AA18, MATCH(TRUE, $B18:$AA18 <> 0, 0))*100))} -> 109.12625 | F28: {=IF(AND(F18=0, ISNA(E28)), NA(), IF(AND(F18<>0, ISNA(E28)), 100, F18/INDEX($B18:$AA18, MATCH(TRUE, $B18:$AA18 <> 0, 0))*100))} -> 111.30198 | G28: {=IF(AND(G18=0, ISNA(F28)), NA(), IF(AND(G18<>0, ISNA(F28)), 100, G18/INDEX($B18:$AA18, MATCH(TRUE, $B18:$AA18 <> 0, 0))*100))} -> 112.80694 | H28: {=IF(AND(H18=0, ISNA(G28)), NA(), IF(AND(H18<>0, ISNA(G28)), 100, H18/INDEX($B18:$AA18, MATCH(TRUE, $B18:$AA18 <> 0, 0))*100))} -> 113.15732 | I28: {=IF(AND(I18=0, ISNA(H28)), NA(), IF(AND(I18<>0, ISNA(H28)), 100, I18/INDEX($B18:$AA18, MATCH(TRUE, $B18:$AA18 <> 0, 0))*100))} -> 111.25847 | J28: {=IF(AND(J18=0, ISNA(I28)), NA(), IF(AND(J18<>0, ISNA(I28)), 100, J18/INDEX($B18:$AA18, MATCH(TRUE, $B18:$AA18 <> 0, 0))*100))} -> 110.93852 | ... AA28: {=IF(AND(AA18=0, ISNA(Z28)), NA(), IF(AND(AA18<>0, ISNA(Z28)), 100, AA18/INDEX($B18:$AA18, MATCH(TRUE, $B18:$AA18 <> 0, 0))*100))} -> 162.95388
A29: Human Capital | B29: =IF(B19=0, NA(), 100) -> 100 | C29: {=IF(AND(C19=0, ISNA(B29)), NA(), IF(AND(C19<>0, ISNA(B29)), 100, C19/INDEX($B19:$AA19, MATCH(TRUE, $B19:$AA19 <> 0, 0))*100))} -> 103.58507 | D29: {=IF(AND(D19=0, ISNA(C29)), NA(), IF(AND(D19<>0, ISNA(C29)), 100, D19/INDEX($B19:$AA19, MATCH(TRUE, $B19:$AA19 <> 0, 0))*100))} -> 108.44859 | E29: {=IF(AND(E19=0, ISNA(D29)), NA(), IF(AND(E19<>0, ISNA(D29)), 100, E19/INDEX($B19:$AA19, MATCH(TRUE, $B19:$AA19 <> 0, 0))*100))} -> 112.50944 | F29: {=IF(AND(F19=0, ISNA(E29)), NA(), IF(AND(F19<>0, ISNA(E29)), 100, F19/INDEX($B19:$AA19, MATCH(TRUE, $B19:$AA19 <> 0, 0))*100))} -> 110.39482 | G29: {=IF(AND(G19=0, ISNA(F29)), NA(), IF(AND(G19<>0, ISNA(F29)), 100, G19/INDEX($B19:$AA19, MATCH(TRUE, $B19:$AA19 <> 0, 0))*100))} -> 109.37386 | H29: {=IF(AND(H19=0, ISNA(G29)), NA(), IF(AND(H19<>0, ISNA(G29)), 100, H19/INDEX($B19:$AA19, MATCH(TRUE, $B19:$AA19 <> 0, 0))*100))} -> 106.67635 | I29: {=IF(AND(I19=0, ISNA(H29)), NA(), IF(AND(I19<>0, ISNA(H29)), 100, I19/INDEX($B19:$AA19, MATCH(TRUE, $B19:$AA19 <> 0, 0))*100))} -> 102.45997 | J29: {=IF(AND(J19=0, ISNA(I29)), NA(), IF(AND(J19<>0, ISNA(I29)), 100, J19/INDEX($B19:$AA19, MATCH(TRUE, $B19:$AA19 <> 0, 0))*100))} -> 110.68551 | ... AA29: {=IF(AND(AA19=0, ISNA(Z29)), NA(), IF(AND(AA19<>0, ISNA(Z29)), 100, AA19/INDEX($B19:$AA19, MATCH(TRUE, $B19:$AA19 <> 0, 0))*100))} -> 135.89177
A30: Renewable Natural Capital | B30: =IF(B20=0, NA(), 100) -> 100 | C30: {=IF(AND(C20=0, ISNA(B30)), NA(), IF(AND(C20<>0, ISNA(B30)), 100, C20/INDEX($B20:$AA20, MATCH(TRUE, $B20:$AA20 <> 0, 0))*100))} -> 96.332738 | D30: {=IF(AND(D20=0, ISNA(C30)), NA(), IF(AND(D20<>0, ISNA(C30)), 100, D20/INDEX($B20:$AA20, MATCH(TRUE, $B20:$AA20 <> 0, 0))*100))} -> 97.307491 | E30: {=IF(AND(E20=0, ISNA(D30)), NA(), IF(AND(E20<>0, ISNA(D30)), 100, E20/INDEX($B20:$AA20, MATCH(TRUE, $B20:$AA20 <> 0, 0))*100))} -> 95.061728 | F30: {=IF(AND(F20=0, ISNA(E30)), NA(), IF(AND(F20<>0, ISNA(E30)), 100, F20/INDEX($B20:$AA20, MATCH(TRUE, $B20:$AA20 <> 0, 0))*100))} -> 91.456101 | G30: {=IF(AND(G20=0, ISNA(F30)), NA(), IF(AND(G20<>0, ISNA(F30)), 100, G20/INDEX($B20:$AA20, MATCH(TRUE, $B20:$AA20 <> 0, 0))*100))} -> 93.58197 | H30: {=IF(AND(H20=0, ISNA(G30)), NA(), IF(AND(H20<>0, ISNA(G30)), 100, H20/INDEX($B20:$AA20, MATCH(TRUE, $B20:$AA20 <> 0, 0))*100))} -> 97.204303 | I30: {=IF(AND(I20=0, ISNA(H30)), NA(), IF(AND(I20<>0, ISNA(H30)), 100, I20/INDEX($B20:$AA20, MATCH(TRUE, $B20:$AA20 <> 0, 0))*100))} -> 95.397088 | J30: {=IF(AND(J20=0, ISNA(I30)), NA(), IF(AND(J20<>0, ISNA(I30)), 100, J20/INDEX($B20:$AA20, MATCH(TRUE, $B20:$AA20 <> 0, 0))*100))} -> 93.976115 | ... AA30: {=IF(AND(AA20=0, ISNA(Z30)), NA(), IF(AND(AA20<>0, ISNA(Z30)), 100, AA20/INDEX($B20:$AA20, MATCH(TRUE, $B20:$AA20 <> 0, 0))*100))} -> 67.299227
A31: Nonrenewable Natural Capital | B31: =IF(B21=0, NA(), 100) -> 100 | C31: {=IF(AND(C21=0, ISNA(B31)), NA(), IF(AND(C21<>0, ISNA(B31)), 100, C21/INDEX($B21:$AA21, MATCH(TRUE, $B21:$AA21 <> 0, 0))*100))} -> 106.16177 | D31: {=IF(AND(D21=0, ISNA(C31)), NA(), IF(AND(D21<>0, ISNA(C31)), 100, D21/INDEX($B21:$AA21, MATCH(TRUE, $B21:$AA21 <> 0, 0))*100))} -> 107.13761 | E31: {=IF(AND(E21=0, ISNA(D31)), NA(), IF(AND(E21<>0, ISNA(D31)), 100, E21/INDEX($B21:$AA21, MATCH(TRUE, $B21:$AA21 <> 0, 0))*100))} -> 109.49074 | F31: {=IF(AND(F21=0, ISNA(E31)), NA(), IF(AND(F21<>0, ISNA(E31)), 100, F21/INDEX($B21:$AA21, MATCH(TRUE, $B21:$AA21 <> 0, 0))*100))} -> 118.249 | G31: {=IF(AND(G21=0, ISNA(F31)), NA(), IF(AND(G21<>0, ISNA(F31)), 100, G21/INDEX($B21:$AA21, MATCH(TRUE, $B21:$AA21 <> 0, 0))*100))} -> 116.84497 | H31: {=IF(AND(H21=0, ISNA(G31)), NA(), IF(AND(H21<>0, ISNA(G31)), 100, H21/INDEX($B21:$AA21, MATCH(TRUE, $B21:$AA21 <> 0, 0))*100))} -> 112.3982 | I31: {=IF(AND(I21=0, ISNA(H31)), NA(), IF(AND(I21<>0, ISNA(H31)), 100, I21/INDEX($B21:$AA21, MATCH(TRUE, $B21:$AA21 <> 0, 0))*100))} -> 104.58627 | J31: {=IF(AND(J21=0, ISNA(I31)), NA(), IF(AND(J21<>0, ISNA(I31)), 100, J21/INDEX($B21:$AA21, MATCH(TRUE, $B21:$AA21 <> 0, 0))*100))} -> 97.556338 | ... AA31: {=IF(AND(AA21=0, ISNA(Z31)), NA(), IF(AND(AA21<>0, ISNA(Z31)), 100, AA21/INDEX($B21:$AA21, MATCH(TRUE, $B21:$AA21 <> 0, 0))*100))} -> 31.85029
A32: Foreign Assets | B32: =IF(B22=0, NA(), 100) -> 100 | C32: {=IF(AND(C22=0, ISNA(B32)), NA(), IF(AND(C22<>0, ISNA(B32)), 100, C22/INDEX($B22:$AA22, MATCH(TRUE, $B22:$AA22 <> 0, 0))*100))} -> 113.45417 | D32: {=IF(AND(D22=0, ISNA(C32)), NA(), IF(AND(D22<>0, ISNA(C32)), 100, D22/INDEX($B22:$AA22, MATCH(TRUE, $B22:$AA22 <> 0, 0))*100))} -> 128.749 | E32: {=IF(AND(E22=0, ISNA(D32)), NA(), IF(AND(E22<>0, ISNA(D32)), 100, E22/INDEX($B22:$AA22, MATCH(TRUE, $B22:$AA22 <> 0, 0))*100))} -> 134.23629 | F32: {=IF(AND(F22=0, ISNA(E32)), NA(), IF(AND(F22<>0, ISNA(E32)), 100, F22/INDEX($B22:$AA22, MATCH(TRUE, $B22:$AA22 <> 0, 0))*100))} -> 145.58834 | G32: {=IF(AND(G22=0, ISNA(F32)), NA(), IF(AND(G22<>0, ISNA(F32)), 100, G22/INDEX($B22:$AA22, MATCH(TRUE, $B22:$AA22 <> 0, 0))*100))} -> 145.94784 | H32: {=IF(AND(H22=0, ISNA(G32)), NA(), IF(AND(H22<>0, ISNA(G32)), 100, H22/INDEX($B22:$AA22, MATCH(TRUE, $B22:$AA22 <> 0, 0))*100))} -> 127.74364 | I32: {=IF(AND(I22=0, ISNA(H32)), NA(), IF(AND(I22<>0, ISNA(H32)), 100, I22/INDEX($B22:$AA22, MATCH(TRUE, $B22:$AA22 <> 0, 0))*100))} -> 98.687829 | J32: {=IF(AND(J22=0, ISNA(I32)), NA(), IF(AND(J22<>0, ISNA(I32)), 100, J22/INDEX($B22:$AA22, MATCH(TRUE, $B22:$AA22 <> 0, 0))*100))} -> 95.540748 | ... AA32: {=IF(AND(AA22=0, ISNA(Z32)), NA(), IF(AND(AA22<>0, ISNA(Z32)), 100, AA22/INDEX($B22:$AA22, MATCH(TRUE, $B22:$AA22 <> 0, 0))*100))} -> 27.71366
A33: Foreign Liabilities | B33: =IF(B23=0, NA(), 100) -> 100 | C33: {=IF(AND(C23=0, ISNA(B33)), NA(), IF(AND(C23<>0, ISNA(B33)), 100, C23/INDEX($B23:$AA23, MATCH(TRUE, $B23:$AA23 <> 0, 0))*100))} -> 112.40754 | D33: {=IF(AND(D23=0, ISNA(C33)), NA(), IF(AND(D23<>0, ISNA(C33)), 100, D23/INDEX($B23:$AA23, MATCH(TRUE, $B23:$AA23 <> 0, 0))*100))} -> 130.38142 | E33: {=IF(AND(E23=0, ISNA(D33)), NA(), IF(AND(E23<>0, ISNA(D33)), 100, E23/INDEX($B23:$AA23, MATCH(TRUE, $B23:$AA23 <> 0, 0))*100))} -> 140.27293 | F33: {=IF(AND(F23=0, ISNA(E33)), NA(), IF(AND(F23<>0, ISNA(E33)), 100, F23/INDEX($B23:$AA23, MATCH(TRUE, $B23:$AA23 <> 0, 0))*100))} -> 148.5865 | G33: {=IF(AND(G23=0, ISNA(F33)), NA(), IF(AND(G23<>0, ISNA(F33)), 100, G23/INDEX($B23:$AA23, MATCH(TRUE, $B23:$AA23 <> 0, 0))*100))} -> 150.21746 | H33: {=IF(AND(H23=0, ISNA(G33)), NA(), IF(AND(H23<>0, ISNA(G33)), 100, H23/INDEX($B23:$AA23, MATCH(TRUE, $B23:$AA23 <> 0, 0))*100))} -> 156.53327 | I33: {=IF(AND(I23=0, ISNA(H33)), NA(), IF(AND(I23<>0, ISNA(H33)), 100, I23/INDEX($B23:$AA23, MATCH(TRUE, $B23:$AA23 <> 0, 0))*100))} -> 100.04759 | J33: {=IF(AND(J23=0, ISNA(I33)), NA(), IF(AND(J23<>0, ISNA(I33)), 100, J23/INDEX($B23:$AA23, MATCH(TRUE, $B23:$AA23 <> 0, 0))*100))} -> 93.278245 | ... AA33: {=IF(AND(AA23=0, ISNA(Z33)), NA(), IF(AND(AA23<>0, ISNA(Z33)), 100, AA23/INDEX($B23:$AA23, MATCH(TRUE, $B23:$AA23 <> 0, 0))*100))} -> 14.70819
A84: =CONCATENATE("Nominal Wealth Shares (current US$) - ",$A$3) -> Nominal Wealth Shares (current US$) - Argentina
A85: =CONCATENATE("Nominal Wealth Shares - ",$A$3) -> Nominal Wealth Shares - Argentina | B85: 1995 | C85: 1996 | D85: 1997 | E85: 1998 | F85: 1999 | G85: 2000 | H85: 2001 | I85: 2002 | J85: 2003 | K85: 2004 | L85: 2005 | M85: 2006 | N85: 2007 | O85: 2008 | P85: 2009 | Q85: 2010 | R85: 2011 | S85: 2012 | T85: 2013 | U85: 2014 | V85: 2015 | W85: 2016 | X85: 2017 | Y85: 2018 | Z85: 2019 | AA85: 2020
A86: Produced capital | B86: ='Select a Country'!C74 -> 0.31330627 | C86: ='Select a Country'!D74 -> 0.30014613 | D86: ='Select a Country'!E74 -> 0.28618112 | E86: ='Select a Country'!F74 -> 0.27988172 | F86: ='Select a Country'!G74 -> 0.2896646 | G86: ='Select a Country'!H74 -> 0.27979687 | H86: ='Select a Country'!I74 -> 0.2943005 | I86: ='Select a Country'!J74 -> 0.36726385 | ... AA86: ='Select a Country'!AB74 -> 0.26685741
A87: Human capital | B87: ='Select a Country'!C75 -> 0.55979691 | C87: ='Select a Country'!D75 -> 0.57247167 | D87: ='Select a Country'!E75 -> 0.58772041 | E87: ='Select a Country'!F75 -> 0.60857754 | F87: ='Select a Country'!G75 -> 0.60605695 | G87: ='Select a Country'!H75 -> 0.59745977 | H87: ='Select a Country'!I75 -> 0.59894821 | I87: ='Select a Country'!J75 -> 0.44442883 | ... AA87: ='Select a Country'!AB75 -> 0.63924054
A88: Renewable Natural Capital | B88: ='Select a Country'!C76 -> 0.1120247 | C88: ='Select a Country'!D76 -> 0.10850416 | D88: ='Select a Country'!E76 -> 0.10941097 | E88: ='Select a Country'!F76 -> 0.098973977 | F88: ='Select a Country'!G76 -> 0.086696495 | G88: ='Select a Country'!H76 -> 0.088761428 | H88: ='Select a Country'!I76 -> 0.084125413 | I88: ='Select a Country'!J76 -> 0.12225081 | ... AA88: ='Select a Country'!AB76 -> 0.082865331
A89: Nonrenewable Natural capital | B89: ='Select a Country'!C77 -> 0.014872112 | C89: ='Select a Country'!D77 -> 0.018878048 | D89: ='Select a Country'!E77 -> 0.016687496 | E89: ='Select a Country'!F77 -> 0.012566766 | F89: ='Select a Country'!G77 -> 0.017581955 | G89: ='Select a Country'!H77 -> 0.033981931 | H89: ='Select a Country'!I77 -> 0.022625877 | I89: ='Select a Country'!J77 -> 0.066056509 | ... AA89: ='Select a Country'!AB77 -> 0.011036719

Sheet Region
